<robot name="arm_model">

    <!-- Base Link -->
    <link name="base_link">
      <inertial>
        <origin xyz="0 0 0" rpy="0 0 0"/>
        <mass value="0.5"/>
        <inertia ixx="0.0005" iyy="0.0005" izz="0.0005" ixy="0" ixz="0" iyz="0"/>
      </inertial>
      <visual>
        <origin xyz="0 0 0.025" rpy="0 0 0"/>
        <geometry>
          <cylinder radius="0.05" length="0.05"/>
        </geometry>
        <material name="blue">
          <color rgba="0 0 1 1"/>
        </material>
      </visual>
      <collision>
        <origin xyz="0 0 0.025" rpy="0 0 0"/>
        <geometry>
          <cylinder radius="0.025" length="0.05"/>
        </geometry>
      </collision>
    </link>
  
    <!-- Joint 1 (Cylindrical) -->
    <joint name="joint1" type="revolute">
      <parent link="base_link"/>
      <child link="link1"/>
      <origin xyz="0 0 0.05" rpy="0 0 0"/>
      <axis xyz="0 0 1"/>
      <limit effort="10" lower="-1.57" upper="1.57" velocity="1.0"/>
      <dynamics damping="0.1" friction="0.0"/>
    </joint>
  
    <!-- Link 1 -->
    <link name="link1">
      <inertial>
        <origin xyz="0 0 0" rpy="0 0 0"/>
        <mass value="0.25"/>
        <inertia ixx="0.0005" iyy="0.0005" izz="0.0005" ixy="0" ixz="0" iyz="0"/>
      </inertial>
      <visual>
        <origin xyz="0 0 0.125" rpy="0 0 0"/>
        <geometry>
          <cylinder radius="0.03" length="0.25"/>
        </geometry>
        <material name="green">
          <color rgba="0 1 0 1"/>
        </material>
      </visual>
      <collision>
        <origin xyz="0 0 0.125" rpy="0 0 0"/>
        <geometry>
          <cylinder radius="0.015" length="0.25"/>
        </geometry>
      </collision>
    </link>
  
    <!-- Joint 2 (Cylindrical) -->
    <joint name="joint2" type="revolute">
      <parent link="link1"/>
      <child link="link2"/>
      <origin xyz="0 0 0.25" rpy="0 0 0"/>
      <axis xyz="1 0 0"/>
      <limit effort="10" lower="-1.57" upper="1.57" velocity="1.0"/>
      <dynamics damping="0.1" friction="0.0"/>
    </joint>
  
    <!-- Link 2 -->
    <link name="link2">
      <inertial>
        <origin xyz="0 0 0" rpy="0 0 0"/>
        <mass value="0.25"/>
        <inertia ixx="0.0005" iyy="0.0005" izz="0.0005" ixy="0" ixz="0" iyz="0"/>
      </inertial>
      <visual>
        <origin xyz="0 0 0.125" rpy="0 0 0"/>
        <geometry>
          <cylinder radius="0.015" length="0.25"/>
        </geometry>
        <material name="red">
          <color rgba="1 0 0 1"/>
        </material>
      </visual>
      <collision>
        <origin xyz="0 0 0.125" rpy="0 0 0"/>
        <geometry>
          <cylinder radius="0.015" length="0.25"/>
        </geometry>
      </collision>
    </link>
  
    <!-- Static Gripper -->
    <link name="gripper">
      <inertial>
        <origin xyz="0 0 0" rpy="0 0 0"/>
        <mass value="0.1"/>
        <inertia ixx="0.0001" iyy="0.0001" izz="0.0001" ixy="0" ixz="0" iyz="0"/>
      </inertial>
      <visual>
        <origin xyz="0 0 0.05" rpy="0 0 0"/>
        <geometry>
          <box size="0.05 0.01 0.1"/>
        </geometry>
        <material name="gray">
          <color rgba="0.5 0.5 0.5 1"/>
        </material>
      </visual>
      <collision>
        <origin xyz="0 0 0.05" rpy="0 0 0"/>
        <geometry>
          <box size="0.05 0.01 0.1"/>
        </geometry>
      </collision>
    </link>
  
    <!-- Joint 3 (Fixed Gripper) -->
    <joint name="joint3" type="fixed">
      <parent link="link2"/>
      <child link="gripper"/>
      <origin xyz="0 0 0.25" rpy="0 0 0"/>
    </joint>
  
    <!-- Transmission Interface for Joint 1 -->
    <transmission name="transmission_joint1">
      <type>transmission_interface/SimpleTransmission</type>
      <joint name="joint1">
        <hardwareInterface>hardware_interface/PositionJointInterface</hardwareInterface>
      </joint>
      <actuator name="motor1">
        <mechanicalReduction>1</mechanicalReduction>
      </actuator>
    </transmission>
  
    <!-- Transmission Interface for Joint 2 -->
    <transmission name="transmission_joint2">
      <type>transmission_interface/SimpleTransmission</type>
      <joint name="joint2">
        <hardwareInterface>hardware_interface/PositionJointInterface</hardwareInterface>
      </joint>
      <actuator name="motor2">
        <mechanicalReduction>1</mechanicalReduction>
      </actuator>
    </transmission>
    <gazebo>
      <plugin name="gazebo_ros_control" filename="libgazebo_ros_control.so">
        <robotNamespace>/</robotNamespace>
      </plugin>
    </gazebo>
  
  </robot>
  